Workbook

Sheet TOKENOMICS (Cũ)
B2: WC26 NFT FANTASY - FINAL TOKENOMICS
B3: Optimized Based on Strategic Review & Market Reality
B4: Last Updated: February 10, 2026
B6: Token (WorldCup NFT) | D6: $WC26
B7: Network | D7: Polygon
B8: Total Supply (FIXED) | D8: 200000000
B10: CATEGORY | C10: % | D10: TOKENS | E10: PRICE | F10: VALUE | G10: NOTE
B12: TOTAL (1+2+3+4+5+6+7) | C12: =C14+C19+C24+C31+C35+C37+C39 -> 1 | D12: =C12*D$8 -> 200000000
B14: 1. Presale (SEED) | C14: 0.1 | D14: =C14*D$8 -> 20000000 | E14: =F14/D14 -> 0.00375 | F14: =SUM(F15:F17) -> 75000 | G14: Funding for Initial Stage of Project
B15: 1.1. Round 1 - The Vanguard 1 | C15: 0.05 | D15: =C15*D$8 -> 10000000 | E15: 0.0025 | F15: =D15*E15 -> 25000 | G15: 20% (90-day cliff, 240-day linear vesting)
B16: 1.2. Round 2 - The Vanguard 2 | C16: 0.025 | D16: =C16*D$8 -> 5000000 | E16: 0.0045 | F16: =D16*E16 -> 22500 | G16: 20% (90-day cliff, 240-day linear vesting)
B17: 1.3. Round 3 - The Vanguard 3 | C17: 0.025 | D17: =C17*D$8 -> 5000000 | E17: 0.0055 | F17: =D17*E17 -> 27500 | G17: 20% (90-day cliff, 240-day linear vesting)
B19: 2. Community Sale | C19: 0.145 | D19: =C19*D$8 -> 29000000 | E19: =F19/D19 -> 0.0075 | F19: =SUM(F20:F22) -> 217500 | G19: 10% (30-day cliff, 240-day linear vesting)
B20: 2.1. Phase 1 - Whitelist (Airdrop participants, early supporters, KOL communities) | C20: =30%*C19 -> 0.0435 | D20: =C20*D$12 -> 8700000 | E20: =0.0065 -> 0.0065 | F20: =D20*E20 -> 56550 | G20: 10% (30-day cliff, 240-day linear vesting)
B21: 2.2. Phase 2 - Public FCFS (Until Sold out/7 Days) | C21: =40%*C$19 -> 0.058 | D21: =C21*D$12 -> 11600000 | E21: 0.0075 | F21: =D21*E21 -> 87000 | G21: 10% (30-day cliff, 240-day linear vesting)
B22: 2.3. Phase 3 - Lottery (Open 3 Days) | C22: =30%*C$19 -> 0.0435 | D22: =C22*D$12 -> 8700000 | E22: 0.0085 | F22: =D22*E22 -> 73950 | G22: 10% (30-day cliff, 240-day linear vesting)
B24: 3. Game Rewards | C24: =SUM(C25:C29) -> 0.3 | D24: =C24*D$8 -> 60000000 | G24: Dynamic emission, match-based
B25: 3.1. WorldCup 2026 | C25: 0.075 | D25: =C25*D$8 -> 15000000 | G25: Emitted via Squad Fantasy, Oracle Challenge
B26: 3.2. Copa 2027 | C26: 0.05 | D26: =C26*D$8 -> 10000000 | G26: Event-based emission
B27: 3.3. AFCON 2027 | C27: 0.05 | D27: =C27*D$8 -> 10000000 | G27: Event-based emission
B28: 3.4. Asian 2027 | C28: 0.05 | D28: =C28*D$8 -> 10000000 | G28: Event-based emission
B29: 3.5. EURO 2028 | C29: 0.075 | D29: =C29*D$8 -> 15000000 | G29: Event-based emission
B31: 4. Community & Campaigns | C31: 0.125 | D31: =C31*D$8 -> 25000000 | G31: Milestone-based unlock
B32: 4.1. Pre-WC Airdrop & Onboarding | C32: 0.06 | D32: =C32*D$8 -> 12000000 | G32: 20% Pre-Mystery Unlock + 90-Day Linear Vesting (*)
B33: 4.2. Future Campaigns | C33: =C31-C32 -> 0.065 | D33: =C33*D$8 -> 13000000 | G33: DAO-controlled
B35: 5. Team & Advisors | C35: 0.125 | D35: =C35*D$8 -> 25000000 | G35: 20% (90-day cliff, 18-month linear vesting)
B37: 6. Liquidity Pool & Buffer | C37: 0.15 | D37: =C37*D$8 -> 30000000 | G37: Provides liquidity and stability, DAO-managed and replenished by ecosystem revenue
B39: 7. Treasury (Development, OPS, Reserve) | C39: 0.055 | D39: =C39*D$8 -> 11000000 | G39: DAO-managed and replenished by ecosystem activities
B43: (*) 20% of the airdrop will be unlocked 1-5 days before the Mystery Box sale date, followed by daily linear vesting over 90 days for the remaining 80%.

Sheet TOKENOMICS (Mới)
B2: WC26 NFT FANTASY - FINAL TOKENOMICS
B3: Optimized Based on Strategic Review & Market Reality
B4: Last Updated: February 10, 2026
B6: Token (WorldCup NFT) | D6: $WC26
B7: Network | D7: Polygon
B8: Total Supply (FIXED) | D8: 200000000
B10: CATEGORY | C10: % | D10: TOKENS | E10: PRICE | F10: VALUE | G10: NOTE
B12: TOTAL (1+2+3+4+5+6+7) | C12: =C14+C19+C24+C31+C34+C36+C38 -> 1 | D12: =C12*D$8 -> 200000000
B14: 1. Presale (SEED) | C14: 0.1 | D14: =C14*D$8 -> 20000000 | E14: =F14/D14 -> 0.00375 | F14: =SUM(F15:F17) -> 75000 | G14: Funding for Initial Stage of Project
B15: 1.1. Round 1 - The Vanguard 1 | C15: 0.05 | D15: =C15*D$8 -> 10000000 | E15: 0.0025 | F15: =D15*E15 -> 25000 | G15: 20% (90-day cliff, 240-day linear vesting)
B16: 1.2. Round 2 - The Vanguard 2 | C16: 0.025 | D16: =C16*D$8 -> 5000000 | E16: 0.0045 | F16: =D16*E16 -> 22500 | G16: 20% (90-day cliff, 240-day linear vesting)
B17: 1.3. Round 3 - The Vanguard 3 | C17: 0.025 | D17: =C17*D$8 -> 5000000 | E17: 0.0055 | F17: =D17*E17 -> 27500 | G17: 20% (90-day cliff, 240-day linear vesting)
B19: 2. Community Sale | C19: =14.5%+7% -> 0.215 | D19: =C19*D$8 -> 43000000 | E19: =F19/D19 -> 0.0075 | F19: =SUM(F20:F22) -> 322500 | G19: 10% (30-day cliff, 240-day linear vesting)
B20: 2.1. Phase 1 - Whitelist (Airdrop participants, early supporters, KOL communities) | C20: =30%*C19 -> 0.0645 | D20: =C20*D$12 -> 12900000 | E20: =0.0065 -> 0.0065 | F20: =D20*E20 -> 83850 | G20: 10% (30-day cliff, 240-day linear vesting)
B21: 2.2. Phase 2 - Public FCFS (Until Sold out/7 Days) | C21: =40%*C$19 -> 0.086 | D21: =C21*D$12 -> 17200000 | E21: 0.0075 | F21: =D21*E21 -> 129000 | G21: 10% (30-day cliff, 240-day linear vesting)
B22: 2.3. Phase 3 - Lottery (Open 3 Days) | C22: =30%*C$19 -> 0.0645 | D22: =C22*D$12 -> 12900000 | E22: 0.0085 | F22: =D22*E22 -> 109650 | G22: 10% (30-day cliff, 240-day linear vesting)
B24: 3. Game Rewards | C24: =SUM(C25:C29) -> 0.3 | D24: =C24*D$8 -> 60000000 | G24: Dynamic emission, match-based
B25: 3.1. WorldCup 2026 | C25: 0.075 | D25: =C25*D$8 -> 15000000 | G25: Emitted via Squad Fantasy, Oracle Challenge
B26: 3.2. Copa 2027 | C26: 0.05 | D26: =C26*D$8 -> 10000000 | G26: Event-based emission
B27: 3.3. AFCON 2027 | C27: 0.05 | D27: =C27*D$8 -> 10000000 | G27: Event-based emission
B28: 3.4. Asian 2027 | C28: 0.05 | D28: =C28*D$8 -> 10000000 | G28: Event-based emission
B29: 3.5. EURO 2028 | C29: 0.075 | D29: =C29*D$8 -> 15000000 | G29: Event-based emission
B31: 4. Community & Campaigns | C31: 0.06 | D31: =C31*D$8 -> 12000000 | E31: (Chuyển 6,5% > Bán Public) | G31: 20% Pre-Mystery Unlock + 90-Day Linear Vesting (*)
B32: (Pre-WC Airdrop & Onboarding)
B34: 5. Team & Advisors | C34: 0.125 | D34: =C34*D$8 -> 25000000 | G34: 20% (90-day cliff, 18-month linear vesting)
B36: 6. Liquidity Pool & Buffer | C36: 0.15 | D36: =C36*D$8 -> 30000000 | G36: Provides liquidity and stability, DAO-managed and replenished by ecosystem revenue
B38: 7. Treasury (Development, OPS, Reserve) | C38: 0.05 | D38: =C38*D$8 -> 10000000 | E38: (Chuyển 0,5% > Bán Public) | G38: DAO-managed and replenished by ecosystem activities
B42: (*) 20% of the airdrop will be unlocked 1-5 days before the Mystery Box sale date, followed by daily linear vesting over 90 days for the remaining 80%.

Sheet SEED
B2: PRE-SALE SEED ROUND SCHEDULE
B4: Pre-sale Schedule | C4: % | D4: WC26 | E4: Price | F4: Value | G4: Note
B5: SEED Round | C5: 0.1 | D5: =SUM(D6:D8) -> 20000000 | E5: =F5/D5 -> 0.00375 | F5: =SUM(F6:F8) -> 75000
B6: Vanguard 1 - The Origin | C6: 0.05 | D6: 10000000 | E6: 0.0025 | F6: =D6*E6 -> 25000 | G6: 10 packs (1M WC26) * 2.500$/Pack
B7: Vanguard 2 - The Pathfinders | C7: 0.025 | D7: 5000000 | E7: 0.0045 | F7: =D7*E7 -> 22500 | G7: 25 packs (200K WC26) * 900$/Pack
B8: Vanguard 3 - The Guardians | C8: 0.025 | D8: 5000000 | E8: 0.0055 | F8: =D8*E8 -> 27500 | G8: 50 packs (100K WC26) * 550$/Pack
B9: (Vesting: 90-day cliff → 20%, Linear 10%/month × 8)
B11: Funds Allocation
B12: Total Round 1 | E12: =SUM(E13:E16) -> 1 | F12: =F5 -> 75000
B13: MVP, Smart Contacts, Airdrops Minigame, Basic-AI | E13: 0.6 | F13: =E13*F12 -> 45000
B14: Marketing System (Social Media, etc...) | E14: 0.2 | F14: =E14*F12 -> 15000
B15: Travel, Meet Up, Marketing, etc | E15: 0.2 | F15: =E15*F12 -> 15000 | G15: (Phân bổ cho thị trường, anh giữ 5%)
B16: Reserve/Contingency
B20: Public Sale | F20: ='PUBLIC-SALE'!F12 -> 322500
B21: MKT | E21: 0.4 | F21: =E21*F20 -> 129000 | G21: =F20-F21 -> 193500
B23: Stadium | F23: =STADIUM!F21 -> 150000
B24: MKT | E24: 0.3 | F24: =E24*F23 -> 45000 | G24: =F23-F24 -> 105000
B26: Mystery Box | F26: =MYSTERY!C19+MYSTERY!D19+MYSTERY!E19 -> 3237000
B27: MKT | E27: 0.35 | F27: =E27*F26 -> 1132950 | G27: =F26-F27 -> 2104050
G29: =SUM(G19:G27) -> 2402550

Sheet PUBLIC-SALE
B2: PRE-SALE SEED ROUND SCHEDULE
B4: Pre-sale Schedule | C4: % | D4: WC26 | E4: Price | F4: Value | G4: Note
B5: Community Launch | C5: ='TOKENOMICS (Cũ)'!C19 -> 0.145 | D5: ='TOKENOMICS (Mới)'!D19 -> 43000000 | E5: =F5/D5 -> 0.0075 | F5: =SUM(F6:F8) -> 322500
B6: Phase 1 - Whitelist (Airdrop participants, early supporters, KOL communities) | C6: 0.3 | D6: =C6*D5 -> 12900000 | E6: 0.0065 | F6: =D6*E6 -> 83850 | G6: Min = 100$
B7: Phase 2 - Public FCFS (Until Sold out/7 Days) | C7: 0.4 | D7: =C7*D5 -> 17200000 | E7: 0.0075 | F7: =D7*E7 -> 129000 | G7: Min = 100$
B8: Round 3 - Lottery (Open 3 Days) | C8: 0.3 | D8: =C8*D5 -> 12900000 | E8: 0.0085 | F8: =D8*E8 -> 109650 | G8: Min = 50$
B11: Funds Allocation
B12: RAISED AS PLAN | E12: =SUM(E13:E16) -> 1 | F12: =F5 -> 322500
B13: Liquidity Pool | E13: 0.45 | F13: =E13*F$12 -> 145125 | G13: DEX liquidity $WC26/USDT on QuickSwap
B14: Marketing Blitz (Khoán cho thị trường) | E14: 0.4 | F14: =E14*F$12 -> 129000 | G14: (Phân bổ cho thị trường, anh giữ 5%)
B15: Operations | E15: 0.15 | F15: =E15*F$12 -> 48375 | G15: Team scalling, Infrastructure costs, Customer support setup
B16: Reserve

Sheet STADIUM
B2: StadiumNFTs AUCTION
B4: No. | C4: Stadium/City | D4: World Cup 2026 Matches | E4: Matches (est.) | F4: Initial Price | G4: Expected Final Price | H4: Note
B5: 1 | C5: MetLife Stadium – NY/NJ | D5: Final | E5: 8 | F5: 15000 | G5: =1.5*F5 -> 22500
B6: 2 | C6: Estadio Azteca – Mexico City | D6: Business Match | E6: 5 | F6: =F7 -> 12500 | G6: =1.5*F6 -> 18750
B7: 3 | C7: SoFi Stadium – Los Angeles | D7: Group + Knockout | E7: 7 | F7: =F8 -> 12500 | G7: =1.5*F7 -> 18750
B8: 4 | C8: AT&T Stadium – Dallas | D8: Group + Knockout | E8: 7 | F8: 12500 | G8: =1.5*F8 -> 18750
B9: 5 | C9: NRG Stadium – Houston | D9: Group | E9: 6 | F9: =F10 -> 10000 | G9: =1.5*F9 -> 15000
B10: 6 | C10: Arrowhead Stadium – Kansas City | D10: Group | E10: 6 | F10: =F11 -> 10000 | G10: =1.5*F10 -> 15000
B11: 7 | C11: Mercedes-Benz Stadium – Atlanta | D11: Group | E11: 6 | F11: =F12 -> 10000 | G11: =1.5*F11 -> 15000
B12: 8 | C12: Lincoln Financial Field – Philadelphia | D12: Group | E12: 6 | F12: =F13 -> 10000 | G12: =1.5*F12 -> 15000
B13: 9 | C13: Hard Rock Stadium – Miami | D13: Group | E13: 6 | F13: 10000 | G13: =1.5*F13 -> 15000
B14: 10 | C14: Levi's Stadium – SF Bay Area | D14: Group | E14: 5 | F14: =F15 -> 7500 | G14: =1.5*F14 -> 11250
B15: 11 | C15: Lumen Field – Seattle | D15: Group | E15: 5 | F15: =F16 -> 7500 | G15: =1.5*F15 -> 11250
B16: 12 | C16: Gillette Stadium – Boston | D16: Group | E16: 5 | F16: =F17 -> 7500 | G16: =1.5*F16 -> 11250
B17: 13 | C17: BC Place – Vancouver | D17: Group | E17: 5 | F17: =F18 -> 7500 | G17: =1.5*F17 -> 11250
B18: 14 | C18: BMO Field – Toronto | D18: Group | E18: 5 | F18: 7500 | G18: =1.5*F18 -> 11250
B19: 15 | C19: Estadio BBVA – Monterrey | D19: Group | E19: 4 | F19: =F20 -> 5000 | G19: =1.5*F19 -> 7500
B20: 16 | C20: Estadio Akron – Guadalajara | D20: Group | E20: 4 | F20: 5000 | G20: =1.5*F20 -> 7500
C21: Total | F21: =SUM(F5:F20) -> 150000 | G21: =SUM(G5:G20) -> 225000
C23: FUNDS ALLOCATION | D23: =SUM(D25:D29) -> 1
C25: Direct Referral (F1=3%, F2=2%) | D25: 0.05 | F25: =D25*F$21 -> 7500
C26: Marketing, and Auction Cost | D26: 0.4 | F26: =D26*F$21 -> 60000 | H26: (+70% tăng thêm do đấu giá)
C27: Binded Artwork Creator(s) | D27: 0.15 | F27: =D27*F$21 -> 22500
C28: Liquidity Pool + Buffer | D28: 0.2 | F28: =D28*F$21 -> 30000
C29: DAO Treasure (OPS) | D29: 0.2 | F29: =D29*F$21 -> 30000

Sheet MYSTERY
B3: Mystery Box | C3: Rising | D3: Elite | E3: Legacy
B4: Quantity of PlayerNFTs | C4: 3 | D4: 5 | E4: 10
B5: NFT Type Probability Breakdown
B6: Common | C6: 0.9 | D6: 0.55 | E6: 0.35
B7: Rare | C7: 0.09 | D7: 0.3 | E7: 0.3
B8: Epic | C8: 0.01 | D8: 0.13 | E8: 0.22
B9: Legendary | C9: - | D9: 0.02 | E9: 0.1
B10: Mythic | C10: - | D10: - | E10: 0.03
B11: Guarantee Rule | D11: At least 1 Rare/Epic | E11: At least 1 Epic
B12: Quantity of Packs: | C12: 120000 | D12: 30000 | E12: 3200
B13: Initial Price, $WC26 | C13: 2500 | D13: 5000 | E13: 15000
B14: Dynamic Pricing Logic | C14: Bonding Curve: 10% increased after 5,000 sold packs. | D14: Bonding Curve: 10% increased after 1,000 sold packs. | E14: Limited Supply: Price Increased upon available packs.
B18: Value in $ (WC26=0,0065) | C18: =0.0065*C13 -> 16.25 | D18: =0.0065*D13 -> 32.5 | E18: =0.0065*E13 -> 97.5
C19: =C12*C18 -> 1950000 | D19: =D12*D18 -> 975000 | E19: =E12*E18 -> 312000 | F19: =SUM(C19:E19) -> 3237000
B21: Total Funds Raised | C21: =SUM(C23:C27) -> 1 | E21: =SUM(E23:E27) -> 3237000
B23: Direct Referral (F1=3%, F2=2%) | C23: 0.05 | D23: =F19 -> 3237000 | E23: =C23*D$23 -> 161850
B24: Marketing, Sales Cost | C24: 0.4 | E24: =C24*D$23 -> 1294800
B25: Binded Artwork Creator(s) | C25: 0.05 | E25: =C25*D$23 -> 161850
B26: Liquidity Pool + Buffer | C26: 0.25 | E26: =C26*D$23 -> 809250
B27: DAO Treasure (OPS) | C27: 0.25 | E27: =C27*D$23 -> 809250

Sheet PLAYER
B3: NFT-Tier | C3: NFT /Player | D3: Players /Team | E3: Total NFT/Team | F3: Players /48 Teams | G3: Total NFT /48 Teams | H3: Note
B4: MYTHIC | C4: 10 | D4: 2 | E4: =C4*D4 -> 20 | F4: =D4*48 -> 96 | G4: =E4*48 -> 960
B5: LEGENDARY | C5: 50 | D5: 4 | E5: =C5*D5 -> 200 | F5: =D5*48 -> 192 | G5: =E5*48 -> 9600
B6: EPIC | C6: 100 | D6: 4 | E6: =C6*D6 -> 400 | F6: =D6*48 -> 192 | G6: =E6*48 -> 19200
B7: RARE | C7: 500 | D7: 6 | E7: =C7*D7 -> 3000 | F7: =D7*48 -> 288 | G7: =E7*48 -> 144000
B8: COMMON | C8: 1000 | D8: 10 | E8: =C8*D8 -> 10000 | F8: =D8*48 -> 480 | G8: =E8*48 -> 480000
B9: TOTAL | D9: =SUM(D4:D8) -> 26 | E9: =SUM(E4:E8) -> 13620 | F9: =SUM(F4:F8) -> 1248 | G9: =SUM(G4:G8) -> 653760

Sheet REVENUE@WC26DIST
B2: IN-GAME-ACTIVITIES INCOME SCHEME
B4: Category | C4: Oracle Challenge | D4: Squad Fantasy | E4: Global Jury MIP/WPP | F4: Primary NFT Drops | G4: Community Creator Hub (MEME Moments) | H4: Transfer Market ($WC26, NFT Trading)
B5: Total | C5: =SUM(C6:C15) -> 1 | D5: =SUM(D6:D15) -> 1 | E5: =SUM(E6:E15) -> 1 | F5: =SUM(F6:F15) -> 1 | G5: =SUM(G6:G15) -> 1 | H5: =SUM(H6:H15) -> 1
B6: Prize Pool (Oracle) | Squads 1-5 | MIP Protocol Authors | Community Creators | C6: 0.6 | D6: 0.6 | E6: 0.6 | F6: 0.6 | G6: 0.6
B7: Protocol Burn | C7: 0.1 | D7: 0.1 | E7: 0.1 | F7: 0.1 | G7: 0.1 | H7: 0.05
B8: Market Fee (Sell in Transfer Market) | F8: 0.05 | G8: 0.05
B9: Referral (F1=3%, F2=2%) | C9: 0.05 | D9: 0.05 | E9: 0.05 | H9: 0.05
B10: Staking Program | C10: 0.05 | D10: 0.05 | E10: 0.05 | F10: 0.05 | G10: 0.05 | H10: 0.3
B11: Stadium NFT Owner | C11: 0.05 | D11: 0.05 | E11: 0.05 | F11: 0.05 | G11: 0.05
B12: DAO Treasure (OPS, Development) | C12: 0.075 | D12: 0.075 | E12: 0.075 | F12: 0.075 | G12: 0.075 | H12: 0.3
B13: Liquidity Buffer | C13: 0.075 | D13: 0.075 | E13: 0.075 | F13: 0.075 | G13: 0.075 | H13: 0.3
B16: World Cup 2026 Rewrads Distribution
B18: Stage | C18: Matches | D18: Tokens/Match | E18: Stage Total
B19: Group Stage | C19: 72 | D19: 100000 | E19: =C19*D19 -> 7200000
B20: Round of 32 | C20: 16 | D20: 150000 | E20: =C20*D20 -> 2400000
B21: Round of 16 | C21: 8 | D21: 200000 | E21: =C21*D21 -> 1600000
B22: Quarter-finals | C22: 4 | D22: 300000 | E22: =C22*D22 -> 1200000
B23: Semi-finals | C23: 2 | D23: 400000 | E23: =C23*D23 -> 800000
B24: Third Place Match | C24: 1 | D24: 500000 | E24: =C24*D24 -> 500000
B25: Final | C25: 1 | D25: 1000000 | E25: =C25*D25 -> 1000000
B26: Subtotal | C26: 104 | E26: =SUM(E19:E25) -> 14700000
B27: Special Awards | E27: 300000
B28: Tournament MVP | E28: 100000
B29: Golden Boot (Top Scorer) | E29: 80000
B30: Golden Glove (Best Goalkeeper) | E30: 80000
B31: Best Young Player | E31: 40000
B32: Total World Cup 2026 | E32: =E26+E27 -> 15000000
B36: TOKENOMICS > GAME REWARDS > World Cup 2026
B37: Total | C37: 1 | D37: ='TOKENOMICS (Cũ)'!D25 -> 15000000
B38: Squad Fantasy Ranking (1-10) | C38: 0.6
B39: Featured Team of the Round | C39: 0.075
B40: Match MVP Reward | C40: 0.025
B41: Oracle Challenge Pool | C41: 0.3
B42: (VIBE = 15%, ORACLE = 15%)

Sheet LIQUIDITY
B3: WC26 NFT FANTASY
B4: Optimized Based on Strategic Review & Market Reality
B5: Last Updated: February 10, 2026
B7: LIQUIDITY & TREASURY
B9: Liquidity Pool: 15% (30M tokens)
B11: BREAKDOWN:
B13: 1. DEX INITIAL SEEDING (50% = 15M tokens):
B14: ├─ Pair: $WC26/USDT on QuickSwap (Polygon)
B15: ├─ Tokens: 15,000,000
B16: ├─ USDT Paired: $84,825 (from Community Sale)
B17: ├─ Initial Price: $0.0065 (matches Community Sale)
B18: ├─ Lock: 6 months minimum
... B110: └─ Healthy, growing, self-sustaining ✅

Sheet Strategic
B3: WC26 NFT FANTASY
B4: Optimized Based on Strategic Review & Market Reality
B5: Last Updated: February 10, 2026
B7: GAME REWARDS (MULTI-TOURNAMENT MODEL)
B9: Total Game Rewards: 30% (60M tokens)
B11: ═══════════════════════════════════════════════════════════════
B12: GAME REWARDS ALLOCATION ACROSS TOURNAMENTS (7-YEAR MODEL)
B13: ═══════════════════════════════════════════════════════════════
B15: PHILOSOPHY:
B17: ✅ WC2026 = 25% of Game Rewards (not 50% or 100%)
B18: ✅ Sustainable: 75% reserved for 5+ future tournaments
B19: ✅ Protects investor dilution (tokens spread over years)
... B22: BREAKDOWN:
B24: 1. WORLD CUP 2026 (Jun-Jul 2026): | C24: 2. COPA AMERICA 2027 (Jun-Jul 2027): | D24: 3. AFRICA CUP 2027 (Jan-Feb 2027): | E24: 4. ASIAN CUP 2027 (Feb 2028):
B25: ├─ % of Game Rewards: 25% | C25: ├─ % of Game Rewards: 18% | D25: ├─ % of Game Rewards: 12% | E25: ├─ % of Game Rewards: 10%
B26: ├─ Tokens: 15,000,000 (7.5% of total supply) | C26: ├─ Tokens: 10,800,000 (5.4% of total supply) | D26: ├─ Tokens: 7,200,000 (3.6% of total supply) | E26: ├─ Tokens: 6,000,000 (3.0% of total supply)
B27: ├─ Matches: 104 total | C27: ├─ Matches: 32 total | D27: ├─ Matches: 52 total | E27: ├─ Matches: 51 total
B28: ├─ Duration: 39 days | C28: ├─ Duration: 31 days | D28: ├─ Duration: 30 days | E28: ├─ Duration: 29 days
B29: └─ Status: PRIMARY FOCUS | C29: └─ Status: PLANNED | D29: └─ Status: PLANNED | E29: └─ Status: PLANNED
B32: 5. EURO 2028 (Jun-Jul 2028): | C32: 6. FUTURE TOURNAMENTS (2029-2032): | D32: 7. EMERGENCY RESERVE:
B33: ├─ % of Game Rewards: 20% | C33: ├─ % of Game Rewards: 10% | D33: ├─ % of Game Rewards: 5%
B34: ├─ Tokens: 12,000,000 (6.0% of total supply) | C34: ├─ Tokens: 6,000,000 (3.0% of total supply) | D34: ├─ Tokens: 3,000,000 (1.5% of total supply)
B35: ├─ Matches: 51 total | C35: ├─ Includes: WC2030, Copa 2031, EURO 2032, etc. | D35: ├─ Use: Unexpected tournaments, bonus rewards
B36: ├─ Duration: 31 days | C36: └─ Status: RESERVED | D36: └─ Governance: DAO vote required
B37: └─ Status: PLANNED
B39: ═══════════════════════════════════════════════════════════════
B40: TOTAL: 100% of Game Rewards (60M tokens) ✅
B41: TIMELINE: 7 years (2026-2032)
B42: ═══════════════════════════════════════════════════════════════
B43: WC2026 Detailed Breakdown (15M tokens)
B44: ═══════════════════════════════════════════════════════════════
B45: WORLD CUP 2026: 15,000,000 tokens (7.5% total supply)
B46: ═══════════════════════════════════════════════════════════════
B48: ALLOCATION BY STAGE:
B50: GROUP STAGE (48 matches): | C50: ROUND OF 16 (8 matches): | D50: QUARTER-FINALS (4 matches):
B51: ├─ Tokens per match: 200,000 | C51: ├─ Tokens per match: 300,000 | D51: ├─ Tokens per match: 400,000
B52: ├─ Total: 9,600,000 tokens | C52: ├─ Total: 2,400,000 tokens | D52: ├─ Total: 1,600,000 tokens
B53: ├─ % of WC2026: 64% | C53: ├─ % of WC2026: 16% | D53: ├─ % of WC2026: 10.7%
B54: ├─ Duration: June 11-27 (17 days) | C54: ├─ Duration: June 29 - July 3 | D54: ├─ Duration: July 5-6
B55: └─ Peak user activity expected | C55: └─ Excitement building | D55: └─ High stakes
...

Sheet Govern_Eligibility
C3: Governance Eligibility Criteria
C5: Criteria | D5: Fan | E5: Contributor | F5: Governor | G5: Vanguard
C6: Staking Amount (Min) | D6: 1,000 WC26 | E6: 10,000 WC26 | F6: 100,000 WC26 | G6: 500,000 WC26
C7: Staking Period | D7: 30 days | E7: 90 days | F7: 180 days | G7: 360 days
C8: Locked Time Before Rights Active | D8: 7 days | E8: 14 days | F8: 30 days | G8: 30 days
C9: KYC Requirement | D9: No required | E9: Email | F9: Email + Phone | G9: Email+ Phone+ID/Passport+Face
C10: Max Voting Weight Cap | D10: 100,000 WC26 | E10: 1,000,000 WC26 | F10: 5,000,000 WC26 | G10: 10,000,000 WC26
C11: Excess Stake Handling | D11: Ignored | E11: Ignored | F11: Ignored | G11: Ignored
C13: Nguồn thưởng STAKING? Tỷ lệ phân bổ
C18: Ai được biểu quyết thay đổi Staking Amount, Period, Locked Time,...?

Sheet LIST-DOCS
B4: Appendix | C4: Title | D4: Visibility
B5: A | C5: (Existing) | D5: —
B6: B | C6: (Existing) | D6: —
B7: C | C7: (Existing) | D7: —
B8: D | C8: Unified Reward Allocation & WC2026 Emission | D8: PUBLIC
B9: E | C9: In-Game NFT Marketplace Fee Model | D9: PUBLIC
B10: F | C10: Oracle & Data Integrity Framework | D10: PUBLIC
B11: G | C11: Liquidity Buffer & AI Risk Control (PIQUE) | D11: PUBLIC
B12: H | C12: Time-Validated Scoring & Settlement Engine | D12: SEMI
B13: I | C13: Technical Settlement & SP Engine | D13: RESTRICTED
C16: DANH MỤC APPENDIX ĐỀ XUẤT – FINAL (SẠCH & CHUẨN)
C18: 📘 PUBLIC
C20: White Paper v1.5 (Final)
C22: APPENDIX A – Unified Rewards & Token Emission
C24: APPENDIX B – Economic Policy Boundaries & System Limits
C26: APPENDIX C – Emergency Scenario Matrix & System Survival
C28: APPENDIX D – Stadium NFT
C30: APPENDIX E – Player NFT
C32: APPENDIX F – Core Games
C33: F(1) Oracle Challenge
C34: F(2) Squad Fantasy
C35: F(3) Global Jury
... C56: (Optional) APPENDIX N – Cross-Tournament Expansion (Internal)
